Exception on / [GET]
Traceback (most recent call last):
  File "/Users/joagabriellima/.local/share/virtualenvs/python-fullstack-template-slfZr8XQ/lib/python3.7/site-packages/flask/app.py", line 2447, in wsgi_app
    response = self.full_dispatch_request()
  File "/Users/joagabriellima/.local/share/virtualenvs/python-fullstack-template-slfZr8XQ/lib/python3.7/site-packages/flask/app.py", line 1952, in full_dispatch_request
    rv = self.handle_user_exception(e)
  File "/Users/joagabriellima/.local/share/virtualenvs/python-fullstack-template-slfZr8XQ/lib/python3.7/site-packages/flask/app.py", line 1821, in handle_user_exception
    reraise(exc_type, exc_value, tb)
  File "/Users/joagabriellima/.local/share/virtualenvs/python-fullstack-template-slfZr8XQ/lib/python3.7/site-packages/flask/_compat.py", line 39, in reraise
    raise value
  File "/Users/joagabriellima/.local/share/virtualenvs/python-fullstack-template-slfZr8XQ/lib/python3.7/site-packages/flask/app.py", line 1950, in full_dispatch_request
    rv = self.dispatch_request()
  File "/Users/joagabriellima/.local/share/virtualenvs/python-fullstack-template-slfZr8XQ/lib/python3.7/site-packages/flask/app.py", line 1936, in dispatch_request
    return self.view_functions[rule.endpoint](**req.view_args)
TypeError: home() got an unexpected keyword argument 'path'
